Workbook

Sheet Read Me
A1: Short-Term Rental / Airbnb ROI & Cash Flow Calculator
A2: How to use this workbook
A4: 1. Go to the 'Inputs' tab. Every cell shaded yellow with blue text is meant for you to edit.
A5: Replace the example numbers with your own property's numbers.
A6: 2. The 'ROI Dashboard' tab updates automatically and shows your key investment metrics:
A7: Cap Rate, Cash-on-Cash Return, NOI, Monthly & Annual Cash Flow, Break-Even Occupancy,
A8: and a 5-Year projection.
A9: 3. The 'Monthly Cash Flow' tab breaks the first year down month by month, with a seasonality
A10: slider per month so you can model peak vs. off-peak booking rates.
A11: 4. Nothing on the Dashboard or Monthly tabs needs editing -- they are all formulas driven by
A12: your Inputs. If a number looks wrong, check the matching Inputs cell first.
A13: 5. All formulas are live Excel/Google Sheets formulas, not pasted values -- change any input
... A23: Verify local short-term-rental regulations, licensing, and taxes before purchasing a property.

Sheet Inputs
A1: Inputs | C1: Yellow + blue cells = edit these. Everything else is a formula.
A3: Property & Purchase
A4: Purchase price | B4: 325000 | C4: Example: mid-size STR in a secondary market
A5: Closing costs (% of price) | B5: 0.03
A6: Furnishing & setup budget | B6: 16000 | C6: Furniture, photography, smart locks, linens, etc.
A7: Down payment (%) | B7: 0.2
A8: Mortgage interest rate (annual) | B8: 0.065
A9: Loan term (years) | B9: 30
A11: Revenue Assumptions
A12: Average nightly rate | B12: 215
A13: Expected occupancy rate | B13: 0.6 | C13: Nights booked / nights available, annual average
A14: Cleaning fee per stay (pass-through) | B14: 90
A15: Average nights per booking | B15: 3.2
A16: Other income per year (parking, pet fee, etc.) | B16: 600
A17: Annual revenue growth rate (for 5-yr projection) | B17: 0.03
A18: Annual expense growth rate (for 5-yr projection) | B18: 0.025
A20: Operating Expenses (annual)
A21: Property management fee (% of revenue) | B21: 0.18
A22: Platform fees, e.g. Airbnb/VRBO (% of revenue) | B22: 0.03
A23: Cleaning & turnover cost (paid to cleaner) | B23: 75 | C23: Per turnover; usually close to the cleaning fee charged
A24: Property taxes (annual) | B24: 3800
A25: Insurance, STR policy (annual) | B25: 2000
A26: Utilities (annual) | B26: 3200
A27: Internet, streaming, software (annual) | B27: 900
A28: Supplies & consumables (annual) | B28: 1200
A29: HOA / licensing / permit fees (annual) | B29: 800
A30: Repairs & maintenance reserve (% of revenue) | B30: 0.05
A32: Derived Purchase Numbers
A33: Total cash to close (down payment + closing + furnishing) | B33: =B4*B7+B4*B5+B6
A34: Loan amount | B34: =B4*(1-B7)
A35: Monthly mortgage payment (P&I) | B35: =-PMT(B8/12,B9*12,B34)

Sheet ROI Dashboard
A1: ROI Dashboard
A2: All values below are formulas driven by the Inputs tab. Nothing here needs editing.
A4: Revenue
A5: Annual nights booked | B5: =365*Inputs!$B$13
A6: Number of bookings per year | B6: =B5/Inputs!$B$15
A7: Gross rental revenue | B7: =Inputs!$B$12*B5
A8: Cleaning fee revenue (pass-through) | B8: =Inputs!$B$14*B6
A9: Other income | B9: =Inputs!$B$16
A10: Total revenue | B10: =SUM(B7:B9)
A12: Operating Expenses
A13: Property management fee | B13: =Inputs!$B$21*B10
A14: Platform fees | B14: =Inputs!$B$22*B10
A15: Cleaning cost (paid to cleaner) | B15: =Inputs!$B$23*B6
A16: Repairs & maintenance reserve | B16: =Inputs!$B$30*B10
A17: Property taxes | B17: =Inputs!$B$24
A18: Insurance | B18: =Inputs!$B$25
A19: Utilities | B19: =Inputs!$B$26
A20: Internet, streaming, software | B20: =Inputs!$B$27
A21: Supplies & consumables | B21: =Inputs!$B$28
A22: HOA / licensing / permits | B22: =Inputs!$B$29
A23: Total operating expenses | B23: =SUM(B13:B22)
A25: Net Operating Income & Cash Flow
A26: Net Operating Income (NOI) | B26: =B10-B23
A27: Annual debt service (mortgage P&I) | B27: =Inputs!$B$35*12
A28: Annual cash flow (pre-tax) | B28: =B26-B27
A29: Monthly cash flow (pre-tax) | B29: =B28/12
A31: Investment Returns
A32: Total cash invested (down payment + closing + furnishing) | B32: =Inputs!$B$33
A33: Cap rate (NOI / purchase price) | B33: =B26/Inputs!$B$4
A34: Cash-on-cash return (cash flow / cash invested) | B34: =B28/B32
A36: Break-Even Occupancy (helper calculation)
A37: Revenue per occupancy point (365 x (ADR + cleaning fee / nights per stay)) | B37: =365*(Inputs!$B$12+Inputs!$B$14/Inputs!$B$15)
A38: Margin retained after %-of-revenue costs | B38: =1-(Inputs!$B$21+Inputs!$B$22+Inputs!$B$30)
A39: Variable cleaning cost per occupancy point (365 x cleaning cost / nights per stay) | B39: =365*Inputs!$B$23/Inputs!$B$15
A40: Fixed annual costs (taxes+insurance+utilities+internet+supplies+HOA+debt service) | B40: =B17+B18+B19+B20+B21+B22+B27
A41: Break-even occupancy rate | B41: =(B40-B38*Inputs!$B$16)/(B38*B37-B39)
A42: Break-even nights booked per year | B42: =B41*365
A44: 5-Year Projection
B45: Year 1 | C45: Year 2 | D45: Year 3 | E45: Year 4 | F45: Year 5
A46: Total revenue | B46: =B10 | C46: =B46*(1+Inputs!$B$17) | D46: =C46*(1+Inputs!$B$17) | E46: =D46*(1+Inputs!$B$17) | F46: =E46*(1+Inputs!$B$17)
...

Sheet Monthly Cash Flow
A1: Monthly Cash Flow (Year 1)
A2: Edit the seasonality factor per month (yellow). 1.00 = average month; 1.30 = 30% above average.
A4: Month | B4: Jan | C4: Feb | D4: Mar | E4: Apr | F4: May | G4: Jun | H4: Jul | I4: Aug | J4: Sep | K4: Oct | L4: Nov | M4: Dec | N4: Total
A5: Seasonality factor | B5: 0.75 | C5: 0.8 | D5: 0.95 | E5: 1.05 | F5: 1.1 | G5: 1.25 | H5: 1.35 | I5: 1.3 | J5: 1.05 | K5: 0.95 | L5: 0.8 | M5: 0.85 | N5: =AVERAGE(B5:M5)
A6: Revenue | B6: =B5/$N$5*'ROI Dashboard'!$B$10/12 | C6: =C5/$N$5*'ROI Dashboard'!$B$10/12 | D6: =D5/$N$5*'ROI Dashboard'!$B$10/12 | E6: =E5/$N$5*'ROI Dashboard'!$B$10/12 | F6: =F5/$N$5*'ROI Dashboard'!$B$10/12 | G6: =G5/$N$5*'ROI Dashboard'!$B$10/12 | H6: =H5/$N$5*'ROI Dashboard'!$B$10/12 | I6: =I5/$N$5*'ROI Dashboard'!$B$10/12 | ... M6: =M5/$N$5*'ROI Dashboard'!$B$10/12 | N6: =SUM(B6:M6)
A7: Operating expenses | B7: =B5/$N$5*'ROI Dashboard'!$B$23/12 | C7: =C5/$N$5*'ROI Dashboard'!$B$23/12 | D7: =D5/$N$5*'ROI Dashboard'!$B$23/12 | E7: =E5/$N$5*'ROI Dashboard'!$B$23/12 | F7: =F5/$N$5*'ROI Dashboard'!$B$23/12 | G7: =G5/$N$5*'ROI Dashboard'!$B$23/12 | H7: =H5/$N$5*'ROI Dashboard'!$B$23/12 | I7: =I5/$N$5*'ROI Dashboard'!$B$23/12 | ... M7: =M5/$N$5*'ROI Dashboard'!$B$23/12 | N7: =SUM(B7:M7)
A8: Mortgage payment (P&I) | B8: =Inputs!$B$35 | C8: =Inputs!$B$35 | D8: =Inputs!$B$35 | E8: =Inputs!$B$35 | F8: =Inputs!$B$35 | G8: =Inputs!$B$35 | H8: =Inputs!$B$35 | I8: =Inputs!$B$35 | ... M8: =Inputs!$B$35 | N8: =SUM(B8:M8)
A9: Net cash flow | B9: =B6-B7-B8 | C9: =C6-C7-C8 | D9: =D6-D7-D8 | E9: =E6-E7-E8 | F9: =F6-F7-F8 | G9: =G6-G7-G8 | H9: =H6-H7-H8 | I9: =I6-I7-I8 | ... M9: =M6-M7-M8 | N9: =SUM(B9:M9)
A10: Cumulative cash flow | B10: =B9 | C10: =B10+C9 | D10: =C10+D9 | E10: =D10+E9 | F10: =E10+F9 | G10: =F10+G9 | H10: =G10+H9 | I10: =H10+I9 | J10: =I10+J9 | ... M10: =L10+M9
